Workbook

Sheet Sheet1
A1: symbol | B1: id | C1: name | D1: vlookup | G1: AVAX': 'avalanche-2'
A2: aapl | B2: twin-asset-token-aapl | C2: TWIN ASSET TOKEN AAPL | D2: =VLOOKUP(A2,Sheet2!$A:$B,1,0) -> #N/A
A3: aapl.d | B3: dinari-aapl-dshares | C3: Dinari AAPL | D3: =VLOOKUP(A3,Sheet2!$A:$B,1,0) -> #N/A
A4: aaplx | B4: apple-xstock | C4: Apple xStock | D4: =VLOOKUP(A4,Sheet2!$A:$B,1,0) -> #N/A
A5: aarb | B5: aave-v3-arb | C5: Aave v3 ARB | D5: =VLOOKUP(A5,Sheet2!$A:$B,1,0) -> #N/A
A6: aark | B6: aark-digital | C6: Aark Digital | D6: =VLOOKUP(A6,Sheet2!$A:$B,1,0) -> #N/A
A7: aart | B7: all-art | C7: ALL.ART | D7: =VLOOKUP(A7,Sheet2!$A:$B,1,0) -> #N/A
A8: aast | B8: aastoken | C8: AASToken | D8: =VLOOKUP(A8,Sheet2!$A:$B,1,0) -> #N/A
A9: aave | B9: aave | C9: Aave | D9: =VLOOKUP(A9,Sheet2!$A:$B,1,0) -> AAVE | F9: ="'"&A9&"'"&":"&"'"&B9&"'"&"," -> 'aave':'aave',
A10: aax | B10: academic-labs | C10: Academic Labs | D10: =VLOOKUP(A10,Sheet2!$A:$B,1,0) -> #N/A
A11: ab | B11: arma-block | C11: Arma Block | D11: =VLOOKUP(A11,Sheet2!$A:$B,1,0) -> #N/A
A12: ab | B12: newton-project | C12: AB | D12: =VLOOKUP(A12,Sheet2!$A:$B,1,0) -> #N/A
A13: abal | B13: aave-bal | C13: Aave BAL | D13: =VLOOKUP(A13,Sheet2!$A:$B,1,0) -> #N/A
A14: abal | B14: aave-v3-bal | C14: Aave v3 BAL | D14: =VLOOKUP(A14,Sheet2!$A:$B,1,0) -> #N/A
A15: abal | B15: arch-balanced-portfolio | C15: Arch Balanced Portfolio | D15: =VLOOKUP(A15,Sheet2!$A:$B,1,0) -> #N/A
A16: abasusdbc | B16: aave-v3-usdbc | C16: Aave v3 aBasUSDbC | D16: =VLOOKUP(A16,Sheet2!$A:$B,1,0) -> #N/A
A17: abat | B17: aave-bat | C17: Aave BAT | D17: =VLOOKUP(A17,Sheet2!$A:$B,1,0) -> #N/A
A18: abat | B18: aave-bat-v1 | C18: Aave BAT v1 | D18: =VLOOKUP(A18,Sheet2!$A:$B,1,0) -> #N/A
A19: abax | B19: abax | C19: Abax | D19: =VLOOKUP(A19,Sheet2!$A:$B,1,0) -> #N/A
A20: abbc | B20: alibabacoin | C20: ABBC | D20: =VLOOKUP(A20,Sheet2!$A:$B,1,0) -> #N/A
A21: abbvx | B21: abbvie-xstock | C21: AbbVie xStock | D21: =VLOOKUP(A21,Sheet2!$A:$B,1,0) -> #N/A
... A100: ad | B100: agent-dora | C100: Agent DORA | D100: =VLOOKUP(A100,Sheet2!$A:$B,1,0) -> #N/A
A101: ada | B101: cardano | C101: Cardano | D101: =VLOOKUP(A101,Sheet2!$A:$B,1,0) -> ADA | F101: ="'"&A101&"'"&":"&"'"&B101&"'"&"," -> 'ada':'cardano',
A102: adacash | B102: adacash | C102: ADAcash | D102: =VLOOKUP(A102,Sheet2!$A:$B,1,0) -> #N/A
A103: adai | B103: aave-dai | C103: Aave DAI | D103: =VLOOKUP(A103,Sheet2!$A:$B,1,0) -> #N/A
A104: adai | B104: aave-dai-v1 | C104: Aave DAI v1 | D104: =VLOOKUP(A104,Sheet2!$A:$B,1,0) -> #N/A
A105: adai | B105: aave-v3-dai | C105: Aave v3 DAI | D105: =VLOOKUP(A105,Sheet2!$A:$B,1,0) -> #N/A
A106: adao | B106: adadao | C106: ADADao | D106: =VLOOKUP(A106,Sheet2!$A:$B,1,0) -> #N/A
A107: adapad | B107: adapad | C107: ADAPad | D107: =VLOOKUP(A107,Sheet2!$A:$B,1,0) -> #N/A
A108: adasol | B108: ada-the-dog | C108: ADA | D108: =VLOOKUP(A108,Sheet2!$A:$B,1,0) -> #N/A
A109: adbe.d | B109: dinari-adbe | C109: Dinari ADBE | D109: =VLOOKUP(A109,Sheet2!$A:$B,1,0) -> #N/A
A110: adco | B110: advertise-coin | C110: Advertise Coin | D110: =VLOOKUP(A110,Sheet2!$A:$B,1,0) -> #N/A
A111: add | B111: add-finance | C111: Add Finance | D111: =VLOOKUP(A111,Sheet2!$A:$B,1,0) -> #N/A
A112: addon | B112: addon-ai | C112: AddOn Ai | D112: =VLOOKUP(A112,Sheet2!$A:$B,1,0) -> #N/A
A113: addy | B113: adamant | C113: Adamant | D113: =VLOOKUP(A113,Sheet2!$A:$B,1,0) -> #N/A
... A433: alfa | B433: alfa-society | C433: alfa.society | D433: =VLOOKUP(A433,Sheet2!$A:$B,1,0) -> #N/A
A434: algo | B434: algorand | C434: Algorand | D434: =VLOOKUP(A434,Sheet2!$A:$B,1,0) -> ALGO | F434: ="'"&A434&"'"&":"&"'"&B434&"'"&"," -> 'algo':'algorand',
A435: algoai | B435: algoritha-a-i | C435: Algoritha A.I | D435: =VLOOKUP(A435,Sheet2!$A:$B,1,0) -> #N/A
A436: algt | B436: algotrade | C436: AlgoTrade | D436: =VLOOKUP(A436,Sheet2!$A:$B,1,0) -> #N/A
A437: ali | B437: alethea-artificial-liquid-intelligence-token | C437: Artificial Liquid Intelligence | D437: =VLOOKUP(A437,Sheet2!$A:$B,1,0) -> #N/A
...

Sheet Sheet2
A1: Ticker
A2: AAVE
A3: ADA
A4: ALGO
A5: APE
A6: APT
A7: ARB
A8: ASR
A9: AVAX
A10: AXS
A11: BCH
A12: BGB
... A47: XRP
